Workbook

Sheet Portada
B2: CATÁLOGO DE ELEMENTOS - CAPA 1
B3: Cámara de Comercio de Pereira (CCP) — Levantamiento arquitectónico
B5: Plano base: | C5: levantamiento camara de coemrcio Pereira FERNANDO V1.dxf (Planta Tipo II)
B6: Aplica a: | C6: Pisos reales 15 y 16 del edificio (planta tipo repetida). NO aplica al Piso 5, que tiene una configuración distinta.
B7: Nomenclatura interna: | C7: OF501–OF506 = las 6 oficinas de la Planta Tipo II, en el orden en que fueron digitalizadas (no corresponden al número de piso real).
B8: Fecha: | C8: 2026-09-13
B9: Elaboró: | C9: Alejandro Grajales Díaz (Ingeniero Civil) — asistido por Claude
B11: RESUMEN DE CANTIDADES
B12: Muros (M) | C12: =COUNTA(Muros!A3:A200) -> 76
B13: Vanos - Ventanas (V) | C13: =COUNTIF(Vanos!B3:B200,"Ventana (V)") -> 9
B14: Vanos - Antepecho+Ventana (AV) | C14: =COUNTIF(Vanos!B3:B200,"Antepecho+Ventana (AV)") -> 6
B15: Vanos - Muro Ventana Baño (MV) | C15: =COUNTIF(Vanos!B3:B200,"Muro Ventana Baño (MV)") -> 6
B16: Rejillas de fachada (R) | C16: =COUNTA(Rejillas_Fachada!A3:A200) -> 4
B17: Buitrones interiores (BT) | C17: =COUNTA(Buitrones!A3:A200) -> 6
B18: Mesones de cocineta (ME) | C18: =COUNTIF(Mobiliario_Fijo!B3:B200,"Mesón cocineta (ME)") -> 6
B19: Jardineras (JA) | C19: =COUNTIF(Mobiliario_Fijo!B3:B200,"Jardinera (JA)") -> 2
B20: Columnas (C) | C20: =COUNTA(Columnas!A3:A200) -> 9
B22: CONVENCIONES DE COLOR
B23: ■ | C23: Dato confirmado / fijo (tomado del levantamiento o de la convención del plano)
B24: ■ | C24: Campo PENDIENTE — el usuario debe diligenciarlo (medición en AutoCAD o en sitio)
B25: ■ | C25: Elemento PENDIENTE DE LEVANTAMIENTO (Punto Fijo) — no se fabrica el dato, se define en visita posterior
B27: NOTAS METODOLÓGICAS
B28: Alturas estándar tomadas de la convención propia del plano (leyenda de Fernando): M = muro h 2.423 m · AV = antepecho 0.925 + ventana 1.50 m · V = ventana h 2.423 m · MV = muro ventana (baño) 2.025 + 0.40 m.
B29: Longitud y Espesor de cada muro/vano NO se incluyen como dato fabricado: se dejan en amarillo para diligenciar directamente en AutoCAD (comando LIST / DIST), evitando reportar una medición no verificada.
B30: Punto Fijo (M72, M74, M75, M76): muros de la escalera/núcleo de acceso cuya altura y vanos no han sido levantados. Se dejan marcados como PENDIENTE, sujetos a una visita de campo posterior (alcance definido explícitamente por el usuario).
B31: Buitrones (BT1-BT6): ductos interiores de ventilación/tubería asociados a los muros MV de cada baño. La cara interior del buitrón no se interviene (queda cerrada); la cara hacia la oficina (muro MV) se interviene según la patología encontrada en el diagnóstico.
B32: Rejillas de fachada (R1-R4) son un elemento DISTINTO de los buitrones: están ubicadas en las 4 esquinas del edificio, en la fachada, y corresponden a los volúmenes que se observan en las fotografías del reventón de ventana en fachada.
B33: MV3 y MV4 quedan ambos en el límite OF503/OF504 (junto al buitrón compartido BT3): se listan como 'OF503/OF504 (BT3 compartido)' porque la heurística geométrica no permite asignar con certeza cuál corresponde a cada oficina — verificar en AutoCAD/sitio antes de asignar de forma definitiva.

Sheet Muros
A1: MUROS (M) — Planta Tipo II
A2: ID | B2: Oficina / Zona | C2: Zona secundaria (muro compartido) | D2: Tipo | E2: Altura (m) | F2: Longitud (m) | G2: Espesor (m) | H2: Observaciones | I2: Área (m²)
A3: M1 | B3: NUCLEO COMUN (ascensores/escalera) | D3: Muro estándar (M) | E3: 2.423 | I3: =IF(AND(F3<>"",G3<>""),F3*G3,"")
A4: M2 | B4: NUCLEO COMUN (ascensores/escalera) | D4: Muro estándar (M) | E4: 2.423 | I4: =IF(AND(F4<>"",G4<>""),F4*G4,"")
A5: M3 | B5: OF501 | C5: OF502 | D5: Muro estándar (M) | E5: 2.423 | H5: Muro divisorio entre oficinas. | I5: =IF(AND(F5<>"",G5<>""),F5*G5,"")
A6: M4 | B6: OF501 | C6: OF502 | D6: Muro estándar (M) | E6: 2.423 | H6: Muro divisorio entre oficinas. | I6: =IF(AND(F6<>"",G6<>""),F6*G6,"")
A7: M5 | B7: OF502 | C7: OF501 | D7: Muro estándar (M) | E7: 2.423 | H7: Muro divisorio entre oficinas. | I7: =IF(AND(F7<>"",G7<>""),F7*G7,"")
A8: M6 | B8: OF502 | C8: OF501 | D8: Muro estándar (M) | E8: 2.423 | H8: Muro divisorio entre oficinas. | I8: =IF(AND(F8<>"",G8<>""),F8*G8,"")
A9: M7 | B9: OF501 | C9: OF502 | D9: Muro estándar (M) | E9: 2.423 | H9: Muro divisorio entre oficinas. | I9: =IF(AND(F9<>"",G9<>""),F9*G9,"")
A10: M8 | B10: OF501 | D10: Muro estándar (M) | E10: 2.423 | I10: =IF(AND(F10<>"",G10<>""),F10*G10,"")
A11: M9 | B11: OF501 | D11: Muro estándar (M) | E11: 2.423 | I11: =IF(AND(F11<>"",G11<>""),F11*G11,"")
A12: M10 | B12: OF502 | C12: OF501 | D12: Muro estándar (M) | E12: 2.423 | H12: Muro divisorio entre oficinas. | I12: =IF(AND(F12<>"",G12<>""),F12*G12,"")
A13: M11 | B13: OF501 | D13: Muro estándar (M) | E13: 2.423 | I13: =IF(AND(F13<>"",G13<>""),F13*G13,"")
A14: M12 | B14: OF501 | D14: Muro estándar (M) | E14: 2.423 | I14: =IF(AND(F14<>"",G14<>""),F14*G14,"")
A15: M13 | B15: OF501 | D15: Muro estándar (M) | E15: 2.423 | I15: =IF(AND(F15<>"",G15<>""),F15*G15,"")
A16: M14 | B16: NUCLEO COMUN (ascensores/escalera) | D16: Muro estándar (M) | E16: 2.423 | I16: =IF(AND(F16<>"",G16<>""),F16*G16,"")
A17: M15 | B17: OF502 | D17: Muro estándar (M) | E17: 2.423 | I17: =IF(AND(F17<>"",G17<>""),F17*G17,"")
A18: M16 | B18: OF502 | D18: Muro estándar (M) | E18: 2.423 | I18: =IF(AND(F18<>"",G18<>""),F18*G18,"")
A19: M17 | B19: OF502 | D19: Muro estándar (M) | E19: 2.423 | I19: =IF(AND(F19<>"",G19<>""),F19*G19,"")
A20: M18 | B20: OF502 | D20: Muro estándar (M) | E20: 2.423 | I20: =IF(AND(F20<>"",G20<>""),F20*G20,"")
A21: M19 | B21: OF502 | D21: Muro estándar (M) | E21: 2.423 | I21: =IF(AND(F21<>"",G21<>""),F21*G21,"")
A22: M20 | B22: OF502 | D22: Muro estándar (M) | E22: 2.423 | I22: =IF(AND(F22<>"",G22<>""),F22*G22,"")
A23: M21 | B23: OF502 | D23: Muro estándar (M) | E23: 2.423 | I23: =IF(AND(F23<>"",G23<>""),F23*G23,"")
A24: M22 | B24: OF503 | C24: OF502 | D24: Muro estándar (M) | E24: 2.423 | H24: Muro divisorio entre oficinas. | I24: =IF(AND(F24<>"",G24<>""),F24*G24,"")
A25: M23 | B25: OF503 | C25: OF502 | D25: Muro estándar (M) | E25: 2.423 | H25: Muro divisorio entre oficinas. | I25: =IF(AND(F25<>"",G25<>""),F25*G25,"")
A26: M24 | B26: OF503 | D26: Muro estándar (M) | E26: 2.423 | I26: =IF(AND(F26<>"",G26<>""),F26*G26,"")
A27: M25 | B27: OF503 | D27: Muro estándar (M) | E27: 2.423 | I27: =IF(AND(F27<>"",G27<>""),F27*G27,"")
A28: M26 | B28: OF503 | C28: OF504 | D28: Muro estándar (M) | E28: 2.423 | H28: Muro divisorio entre oficinas. | I28: =IF(AND(F28<>"",G28<>""),F28*G28,"")
A29: M27 | B29: OF504 | D29: Muro estándar (M) | E29: 2.423 | I29: =IF(AND(F29<>"",G29<>""),F29*G29,"")
A30: M28 | B30: OF503 | C30: OF504 | D30: Muro estándar (M) | E30: 2.423 | H30: Muro divisorio entre oficinas. | I30: =IF(AND(F30<>"",G30<>""),F30*G30,"")
A31: M29 | B31: OF504 | C31: OF503 | D31: Muro estándar (M) | E31: 2.423 | H31: Muro divisorio entre oficinas. | I31: =IF(AND(F31<>"",G31<>""),F31*G31,"")
A32: M30 | B32: OF503 | C32: OF504 | D32: Muro estándar (M) | E32: 2.423 | H32: Muro divisorio entre oficinas. | I32: =IF(AND(F32<>"",G32<>""),F32*G32,"")
A33: M31 | B33: OF503 | D33: Muro estándar (M) | E33: 2.423 | I33: =IF(AND(F33<>"",G33<>""),F33*G33,"")
A34: M32 | B34: OF503 | D34: Muro estándar (M) | E34: 2.423 | I34: =IF(AND(F34<>"",G34<>""),F34*G34,"")
A35: M33 | B35: OF503 | D35: Muro estándar (M) | E35: 2.423 | I35: =IF(AND(F35<>"",G35<>""),F35*G35,"")
A36: M34 | B36: OF503 | D36: Muro estándar (M) | E36: 2.423 | I36: =IF(AND(F36<>"",G36<>""),F36*G36,"")
A37: M35 | B37: OF503 | C37: OF504 | D37: Muro estándar (M) | E37: 2.423 | H37: Muro divisorio entre oficinas. | I37: =IF(AND(F37<>"",G37<>""),F37*G37,"")
A38: M36 | B38: OF504 | C38: OF503 | D38: Muro estándar (M) | E38: 2.423 | H38: Muro divisorio entre oficinas. | I38: =IF(AND(F38<>"",G38<>""),F38*G38,"")
A39: M37 | B39: OF502 | C39: OF504 | D39: Muro estándar (M) | E39: 2.423 | H39: Muro divisorio entre oficinas. | I39: =IF(AND(F39<>"",G39<>""),F39*G39,"")
A40: M38 | B40: OF504 | D40: Muro estándar (M) | E40: 2.423 | I40: =IF(AND(F40<>"",G40<>""),F40*G40,"")
...

Sheet Vanos
A1: VANOS — Ventanas, Antepechos y Muro-Ventana Baño
A2: ID | B2: Tipo | C2: Oficina | D2: Muro asociado (más cercano) | E2: Altura (m) | F2: Longitud (m) | G2: Observaciones
A3: V1 | B3: Ventana (V) | C3: OF501 | D3: M12 | E3: 2.423
A4: V2 | B4: Ventana (V) | C4: OF501 | D4: M11 | E4: 2.423
A5: V3 | B5: Ventana (V) | C5: OF502 | D5: M11 | E5: 2.423
A6: V4 | B6: Ventana (V) | C6: OF503 | D6: M34 | E6: 2.423
A7: V5 | B7: Ventana (V) | C7: OF503 | D7: M34 | E7: 2.423
A8: V6 | B8: Ventana (V) | C8: OF505 | D8: M52 | E8: 2.423
A9: V7 | B9: Ventana (V) | C9: OF505 | D9: M49 | E9: 2.423
A10: V8 | B10: Ventana (V) | C10: OF506 | D10: M50 | E10: 2.423
A11: V9 | B11: Ventana (V) | C11: OF506 | D11: M65 | E11: 2.423
A12: AV1 | B12: Antepecho+Ventana (AV) | C12: OF501 | D12: M1 | G12: Antepecho 0.925 m + Ventana 1.50 m (h. total 2.425 m)
A13: AV2 | B13: Antepecho+Ventana (AV) | C13: OF501 | D13: M13 | G13: Antepecho 0.925 m + Ventana 1.50 m (h. total 2.425 m)
A14: AV3 | B14: Antepecho+Ventana (AV) | C14: OF503 | D14: M31 | G14: Antepecho 0.925 m + Ventana 1.50 m (h. total 2.425 m)
A15: AV4 | B15: Antepecho+Ventana (AV) | C15: OF504 | D15: M41 | G15: Antepecho 0.925 m + Ventana 1.50 m (h. total 2.425 m)
A16: AV5 | B16: Antepecho+Ventana (AV) | C16: OF504 | D16: M53 | G16: Antepecho 0.925 m + Ventana 1.50 m (h. total 2.425 m)
A17: AV6 | B17: Antepecho+Ventana (AV) | C17: OF506 | D17: M63 | G17: Antepecho 0.925 m + Ventana 1.50 m (h. total 2.425 m)
A18: MV1 | B18: Muro Ventana Baño (MV) | C18: OF501 | D18: M7 | G18: Muro 2.025 m + Ventana 0.40 m (baño)
A19: MV2 | B19: Muro Ventana Baño (MV) | C19: OF502 | D19: M16 | G19: Muro 2.025 m + Ventana 0.40 m (baño)
A20: MV3 | B20: Muro Ventana Baño (MV) | C20: OF503/OF504 (BT3 compartido — verificar cuál corresponde a cada oficina) | D20: M27 | G20: Muro 2.025 m + Ventana 0.40 m (baño)
A21: MV4 | B21: Muro Ventana Baño (MV) | C21: OF503/OF504 (BT3 compartido — verificar cuál corresponde a cada oficina) | D21: M27 | G21: Muro 2.025 m + Ventana 0.40 m (baño)
A22: MV5 | B22: Muro Ventana Baño (MV) | C22: OF506 | D22: M54 | G22: Muro 2.025 m + Ventana 0.40 m (baño)
A23: MV6 | B23: Muro Ventana Baño (MV) | C23: NUCLEO COMUN (ascensores/escalera) | D23: M58 | G23: Muro 2.025 m + Ventana 0.40 m (baño)

Sheet Rejillas_Fachada
A1: REJILLAS DE FACHADA (R) — Esquinas del edificio
A2: ID | B2: Ubicación | C2: Oficina cercana | D2: Observaciones
A3: R1 | B3: Esquina del edificio (fachada) | C3: OF501 | D3: Rejilla vertical de fachada en esquina del edificio — confirmada por fotografía (reventón de ventana en esquina) y verificada geométricamente en el levantamiento original y en el DXF de Fernando. Distinta de los buitrones interiores (BT).
A4: R2 | B4: Esquina del edificio (fachada) | C4: OF503 | D4: Rejilla vertical de fachada en esquina del edificio — confirmada por fotografía (reventón de ventana en esquina) y verificada geométricamente en el levantamiento original y en el DXF de Fernando. Distinta de los buitrones interiores (BT).
A5: R3 | B5: Esquina del edificio (fachada) | C5: OF505 | D5: Rejilla vertical de fachada en esquina del edificio — confirmada por fotografía (reventón de ventana en esquina) y verificada geométricamente en el levantamiento original y en el DXF de Fernando. Distinta de los buitrones interiores (BT).
A6: R4 | B6: Esquina del edificio (fachada) | C6: OF506 | D6: Rejilla vertical de fachada en esquina del edificio — confirmada por fotografía (reventón de ventana en esquina) y verificada geométricamente en el levantamiento original y en el DXF de Fernando. Distinta de los buitrones interiores (BT).

Sheet Buitrones
A1: BUITRONES INTERIORES (BT) — Ductos de ventilación/tubería (asociados a muros MV)
A2: ID | B2: Oficina(s) que sirve | C2: Tipo | D2: Regla de intervención | E2: Observaciones
A3: BT1 | B3: OF501 | C3: Independiente | D3: Interior del buitrón: SIN INTERVENCIÓN (queda cerrado). Cara hacia la oficina (muro MV): acabado según patología encontrada en el diagnóstico. | E3: Confirmado por el usuario (levantamiento en campo).
A4: BT2 | B4: OF502 | C4: Independiente | D4: Interior del buitrón: SIN INTERVENCIÓN (queda cerrado). Cara hacia la oficina (muro MV): acabado según patología encontrada en el diagnóstico. | E4: Confirmado por el usuario (levantamiento en campo).
A5: BT3 | B5: OF503 + OF504 | C5: Compartido | D5: Interior del buitrón: SIN INTERVENCIÓN (queda cerrado). Cara hacia la oficina (muro MV): acabado según patología encontrada en el diagnóstico. | E5: Único buitrón compartido entre dos oficinas — confirmado por el usuario.
A6: BT4 | B6: OF505 | C6: Independiente | D6: Interior del buitrón: SIN INTERVENCIÓN (queda cerrado). Cara hacia la oficina (muro MV): acabado según patología encontrada en el diagnóstico. | E6: Confirmado por el usuario (levantamiento en campo).
A7: BT5 | B7: OF506 | C7: Independiente | D7: Interior del buitrón: SIN INTERVENCIÓN (queda cerrado). Cara hacia la oficina (muro MV): acabado según patología encontrada en el diagnóstico. | E7: Confirmado por el usuario (levantamiento en campo).
A8: BT6 | B8: Escalera / Núcleo (junto a OF506) | C8: Independiente | D8: Interior del buitrón: SIN INTERVENCIÓN (queda cerrado). Cara hacia la oficina (muro MV): acabado según patología encontrada en el diagnóstico. | E8: Adicionado por el usuario directamente en AutoCAD, junto a la escalera, al lado de la oficina 6. Mismo patrón de ducto de ventilación de baño que BT1-BT5.

Sheet Mobiliario_Fijo
A1: MOBILIARIO FIJO — Mesones de cocineta y Jardineras
A2: ID | B2: Tipo | C2: Oficina / Zona | D2: Profundidad (m) | E2: Altura (m) | F2: Longitud (m) | G2: Observaciones
A3: ME1 | B3: Mesón cocineta (ME) | C3: OF501 / OF502 | D3: 0.6 | G3: Profundidad fija 0.6 m; longitud variable — medir en AutoCAD/sitio.
A4: ME2 | B4: Mesón cocineta (ME) | C4: OF502 / OF501 | D4: 0.6 | G4: Profundidad fija 0.6 m; longitud variable — medir en AutoCAD/sitio.
A5: ME3 | B5: Mesón cocineta (ME) | C5: OF504 / OF503 | D5: 0.6 | G5: Profundidad fija 0.6 m; longitud variable — medir en AutoCAD/sitio.
A6: ME4 | B6: Mesón cocineta (ME) | C6: OF504 / OF503 | D6: 0.6 | G6: Profundidad fija 0.6 m; longitud variable — medir en AutoCAD/sitio.
A7: ME5 | B7: Mesón cocineta (ME) | C7: OF505 | D7: 0.6 | G7: Profundidad fija 0.6 m; longitud variable — medir en AutoCAD/sitio.
A8: ME6 | B8: Mesón cocineta (ME) | C8: NUCLEO COMUN (ascensores/escalera) | D8: 0.6 | G8: Profundidad fija 0.6 m; longitud variable — medir en AutoCAD/sitio.
A9: JA1 | B9: Jardinera (JA) | C9: NUCLEO COMUN (ascensores/escalera) | E9: 0.7 | G9: Altura fija 0.70 m, ubicada en el descanso de la escalera. Longitud — medir en AutoCAD/sitio.
A10: JA2 | B10: Jardinera (JA) | C10: NUCLEO COMUN (ascensores/escalera) | E10: 0.7 | G10: Altura fija 0.70 m, ubicada en el descanso de la escalera. Longitud — medir en AutoCAD/sitio.

Sheet Columnas
A1: COLUMNAS (C) — Estructura
A2: ID | B2: Oficina / Zona | C2: Observaciones
A3: C1 | B3: OF501 | C3: Sección y refuerzo — sujeto a evaluación estructural independiente.
A4: C2 | B4: OF502 | C4: Sección y refuerzo — sujeto a evaluación estructural independiente.
A5: C3 | B5: OF503 | C5: Sección y refuerzo — sujeto a evaluación estructural independiente.
A6: C4 | B6: OF504 | C6: Sección y refuerzo — sujeto a evaluación estructural independiente.
A7: C5 | B7: NUCLEO COMUN (ascensores/escalera) | C7: Sección y refuerzo — sujeto a evaluación estructural independiente.
A8: C6 | B8: NUCLEO COMUN (ascensores/escalera) | C8: Sección y refuerzo — sujeto a evaluación estructural independiente.
A9: C7 | B9: OF505 | C9: Sección y refuerzo — sujeto a evaluación estructural independiente.
A10: C8 | B10: OF506 / OF505 | C10: Sección y refuerzo — sujeto a evaluación estructural independiente.
A11: C9 | B11: OF506 | C11: Sección y refuerzo — sujeto a evaluación estructural independiente.
